Workbook

Sheet Vue d'ensemble
B2: AvicoleGuard — Suivi de développement du projet
B3: Sprints de 2 semaines — basé sur le backlog EPIC/User Stories et la roadmap MVP (V1) du cahier des charges final
B5: Légende statut : | D5: À faire | E5: En cours | F5: Bloqué | G5: Terminé
B7: Sprint | C7: Dates (à remplir) | D7: Phase roadmap associée | E7: Objectif du sprint | F7: EPICs couverts | G7: Nb User Stories | H7: Statut global | I7: Avancement (%)
B8: Sprint 0 | D8: Phase 0-1 — Analyse & Architecture | E8: Cadrage validé, setup dépôt Django + Docker Compose + CI de base, ADR figées | F8: Setup projet | G8: 0 | H8: À faire | I8: 0
B9: Sprint 1 | D9: Phase 2 — Backend Django (socle) | E9: Auth (accounts), Farms, Flocks opérationnels avec permissions de base | F9: Authentification & Comptes ; Gestion des exploitations et lots | G9: 5 | H9: À faire | I9: 0
B10: Sprint 2 | D10: Phase 3 — Base PostgreSQL | E10: Schéma complet migré, Django Admin de base pour AlertRule/EducationalContent | F10: Sécurité & Audit (base) | G10: 3 | H10: À faire | I10: 0
B11: Sprint 3 | D11: Phase 4 — App Flutter (core online) | E11: Écrans auth, exploitations, lots connectés à l'API en mode online | F11: Gestion des exploitations et lots (mobile) | G11: 4 | H11: À faire | I11: 0
B12: Sprint 4 | D12: Phase 2-3 — Suivi terrain | E12: Suivi quotidien, mortalité (+ verrou RM4), annulation tracée (RM11), observations | F12: Suivi terrain | G12: 5 | H12: À faire | I12: 0
B13: Sprint 5 | D13: Phase 5 — Offline-first | E13: SQLite local, sync_queue, SyncQueueWorker, endpoints push/pull idempotents | F13: Synchronisation offline | G13: 4 | H13: À faire | I13: 0
B14: Sprint 6 | D14: Phase 6 — Moteur de règles & alertes | E14: AlertRuleEvaluator (seuil + tendance), anti-répétition RM12, alertes, recommandations | F14: Moteur d'analyse & alertes | G14: 5 | H14: À faire | I14: 0
B15: Sprint 7 | D15: Phase 7 — Assistance vétérinaire | E15: Demande, affectation manuelle, réponse, historique | F15: Assistance vétérinaire | G15: 3 | H15: À faire | I15: 0
B16: Sprint 8 | D16: Phase 6-7 (suite) — Contenus & notifications | E16: Contenus éducatifs (lecture), notifications in-app, calendrier sanitaire (planification manuelle) | F16: Contenus éducatifs & Back-office admin | G16: 2 | H16: À faire | I16: 0
B17: Sprint 9 | D17: Phase 8 — Durcissement & Tests | E17: Tests Security/Sync complets, rate limiting, revue sécurité, KPI instrumentés | F17: Sécurité & Audit (durcissement) | G17: 3 | H17: À faire | I17: 0
B18: Sprint 10 | D18: Phase 9 — Déploiement | E18: Docker prod (+ Celery worker/beat), CI/CD, monitoring de base, health check | F18: Déploiement | G18: 0 | H18: À faire | I18: 0
B19: Sprint 11 | D19: Phase 10 — Pilote terrain | E19: Formation éleveurs pilotes, collecte de retours, corrections bloquantes | F19: Pilote terrain | G19: 0 | H19: À faire | I19: 0

Sheet Backlog détaillé
A1: Backlog détaillé — EPIC / User Story / Tâches
A2: Une ligne = une tâche. Mettre à jour Statut, Responsable, Estimation réelle au fil du sprint.
A4: Sprint | B4: EPIC | C4: User Story (ID) | D4: Tâche | E4: Type | F4: Priorité | G4: Statut | H4: Estim. (j) | I4: Responsable | J4: Sync/Offline ? | K4: Notes
A5: Sprint 0 | B5: Setup projet | C5: SET-001 | D5: Setup dépôt Django + apps skeleton + Docker Compose (app, postgres, redis, celery-worker, celery-beat, nginx) | E5: DevOps | F5: Must | G5: À faire
A6: Sprint 0 | B6: Setup projet | C6: SET-002 | D6: Configurer CI (lint, tests, build image) — GitHub Actions ou équivalent | E6: DevOps | F6: Must | G6: À faire
A7: Sprint 0 | B7: Setup projet | C7: SET-003 | D7: drf-spectacular configuré, squelette OpenAPI accessible | E7: Backend | F7: Should | G7: À faire
A8: Sprint 1 | B8: Authentification & Comptes | C8: US-AUTH-001 | D8: Inscription éleveur (modèle User custom, serializer, vue, tests) | E8: Backend | F8: Must | G8: À faire
A9: Sprint 1 | B9: Authentification & Comptes | C9: US-AUTH-001 | D9: Écran Register Flutter + validation locale + gestion erreurs 422 | E9: Mobile | F9: Must | G9: À faire | J9: Non
A10: Sprint 1 | B10: Authentification & Comptes | C10: US-AUTH-002 | D10: Connexion (SimpleJWT access/refresh) + tests | E10: Backend | F10: Must | G10: À faire
A11: Sprint 1 | B11: Authentification & Comptes | C11: US-AUTH-002 | D11: Écran Login Flutter, stockage sécurisé du token | E11: Mobile | F11: Must | G11: À faire | J11: Non
A12: Sprint 1 | B12: Authentification & Comptes | C12: US-AUTH-003 | D12: Mot de passe oublié (lien à usage unique, expiration 60 min) | E12: Backend | F12: Must | G12: À faire
A13: Sprint 1 | B13: Gestion des exploitations et lots | C13: US-FARM-001 | D13: Modèle Farm + FarmViewSet + IsFarmOwner permission + tests | E13: Backend | F13: Must | G13: À faire
A14: Sprint 1 | B14: Gestion des exploitations et lots | C14: US-FLOCK-001 | D14: Modèle Flock + FlockViewSet + tests (contrainte current_count<=initial_count) | E14: Backend | F14: Must | G14: À faire
A15: Sprint 2 | B15: Sécurité & Audit (base) | C15: US-SEC-001 | D15: Permission classes systématiques (IsFlockOwner, IsFarmOwner) sur toutes les ressources | E15: Backend | F15: Must | G15: À faire
A16: Sprint 2 | B16: Sécurité & Audit (base) | C16: US-SEC-002 | D16: App audit : modèle AuditLog + signal post_save sur actions sensibles | E16: Backend | F16: Should | G16: À faire
A17: Sprint 2 | B17: Sécurité & Audit (base) | C17: US-ADMIN-001 | D17: Enregistrement Django Admin : AlertRule, EducationalContent, ContentCategory | E17: Backend | F17: Should | G17: À faire
A18: Sprint 2 | B18: Sécurité & Audit (base) | C18: US-DB-001 | D18: Migrations complètes des 3 apps existantes rejouables sur base vierge + seeders (rôles, catégories, règles d'alerte) | E18: Backend | F18: Must | G18: À faire
A19: Sprint 3 | B19: Gestion des exploitations et lots (mobile) | C19: US-FARM-001b | D19: Écran liste/détail exploitations Flutter (mode online) | E19: Mobile | F19: Must | G19: À faire | J19: Non
A20: Sprint 3 | B20: Gestion des exploitations et lots (mobile) | C20: US-FLOCK-001b | D20: Écran création/détail lot Flutter (mode online) | E20: Mobile | F20: Must | G20: À faire | J20: Non
A21: Sprint 3 | B21: Gestion des exploitations et lots (mobile) | C21: US-FLOCK-002 | D21: Clôture d'un lot (API + écran) — refuse toute saisie ultérieure (RM7) | E21: Backend | F21: Must | G21: À faire
A22: Sprint 3 | B22: Gestion des exploitations et lots (mobile) | C22: US-UX-001 | D22: Dashboard éleveur (7 indicateurs max, §32 cahier final) | E22: Mobile | F22: Should | G22: À faire | J22: Non
A23: Sprint 4 | B23: Suivi terrain | C23: US-MON-001 | D23: Modèle DailyMonitoring + endpoint + tests | E23: Backend | F23: Must | G23: À faire
A24: Sprint 4 | B24: Suivi terrain | C24: US-MON-001b | D24: Écran saisie suivi quotidien Flutter, valeurs par défaut pré-remplies | E24: Mobile | F24: Must | G24: À faire | J24: Oui
A25: Sprint 4 | B25: Suivi terrain | C25: US-MORT-001 | D25: Déclaration mortalité + verrou transactionnel select_for_update (RM4) | E25: Backend | F25: Must | G25: À faire
A26: Sprint 4 | B26: Suivi terrain | C26: US-MORT-002 | D26: Annulation mortalité tracée (RM11) : cancelled_at/cancel_reason + recalcul current_count + AuditLog | E26: Backend | F26: Must | G26: À faire
A27: Sprint 4 | B27: Suivi terrain | C27: US-MORT-002b | D27: Écran annulation (motif obligatoire) accessible depuis l'historique du lot | E27: Mobile | F27: Must | G27: À faire | J27: Oui
A28: Sprint 4 | B28: Suivi terrain | C28: US-OBS-001 | D28: Déclaration observation sanitaire (types normalisés) + tests | E28: Backend | F28: Must | G28: À faire
A29: Sprint 5 | B29: Synchronisation offline | C29: US-SYNC-001 | D29: Couche SQLite locale (Drift) + table sync_queue côté Flutter | E29: Mobile | F29: Must | G29: À faire | J29: Oui
A30: Sprint 5 | B30: Synchronisation offline | C30: US-SYNC-001b | D30: SyncQueueWorker (retry backoff exponentiel, statuts pending/syncing/synced/failed/conflict) | E30: Mobile | F30: Must | G30: À faire | J30: Oui
A31: Sprint 5 | B31: Synchronisation offline | C31: US-SYNC-002 | D31: Endpoint POST /sync/{entity} idempotent par client_uuid | E31: Backend | F31: Must | G31: À faire
A32: Sprint 5 | B32: Synchronisation offline | C32: US-SYNC-003 | D32: Endpoint GET /sync/pull?since= (synchronisation incrémentale) | E32: Backend | F32: Must | G32: À faire
A33: Sprint 5 | B33: Synchronisation offline | C33: US-SYNC-004 | D33: Résolution de conflit (dernier gagnant serveur + notification utilisateur) | E33: Backend | F33: Must | G33: À faire
A34: Sprint 5 | B34: Synchronisation offline | C34: US-SYNC-005 | D34: Tests de synchronisation : création offline, rejeu idempotent, retry, conflit simulé | E34: Tests | F34: Must | G34: À faire | J34: Oui
A35: Sprint 6 | B35: Moteur d'analyse & alertes | C35: US-HEALTH-001 | D35: AlertRuleEvaluator — règle mortality_threshold (Celery task analyze_flock) | E35: Backend | F35: Must | G35: À faire
A36: Sprint 6 | B36: Moteur d'analyse & alertes | C36: US-HEALTH-002 | D36: Règles water/feed_consumption_drop, weight_deviation, temperature_abnormality (tendance trend_window_days) | E36: Backend | F36: Must | G36: À faire
A37: Sprint 6 | B37: Moteur d'analyse & alertes | C37: US-HEALTH-003 | D37: Anti-répétition d'alerte (RM12, fenêtre 24h) + calcul confidence | E37: Backend | F37: Must | G37: À faire
A38: Sprint 6 | B38: Moteur d'analyse & alertes | C38: US-ALERT-001 | D38: Génération Alert + Recommendation liées, wording RM9 ("signal, pas diagnostic") | E38: Backend | F38: Must | G38: À faire
A39: Sprint 6 | B39: Moteur d'analyse & alertes | C39: US-ALERT-002 | D39: Écran Alertes Flutter (code couleur par niveau) + acquittement/clôture | E39: Mobile | F39: Must | G39: À faire | J39: Non
A40: Sprint 7 | B40: Assistance vétérinaire | C40: US-ASSIST-001 | D40: Création demande d'assistance (+ upload photo sécurisé, URL signée) | E40: Backend | F40: Must | G40: À faire
A41: Sprint 7 | B41: Assistance vétérinaire | C41: US-ASSIST-002 | D41: Réponse professionnel + historique complet (fil de discussion) | E41: Backend | F41: Must | G41: À faire
...

Sheet Avancement
B2: Avancement global (calculé automatiquement depuis l'onglet 'Backlog détaillé')
B4: Sprint | C4: Nb tâches | D4: Terminées | E4: En cours | F4: Bloquées | G4: % Terminé
B5: Sprint 0 | C5: =COUNTIF('Backlog détaillé'!A:A,B5) -> 3 | D5: =COUNTIFS('Backlog détaillé'!A:A,B5,'Backlog détaillé'!G:G,"Terminé") -> 0 | E5: =COUNTIFS('Backlog détaillé'!A:A,B5,'Backlog détaillé'!G:G,"En cours") -> 0 | F5: =COUNTIFS('Backlog détaillé'!A:A,B5,'Backlog détaillé'!G:G,"Bloqué") -> 0 | G5: =IFERROR(D5/C5,0) -> 0
B6: Sprint 1 | C6: =COUNTIF('Backlog détaillé'!A:A,B6) -> 7 | D6: =COUNTIFS('Backlog détaillé'!A:A,B6,'Backlog détaillé'!G:G,"Terminé") -> 0 | E6: =COUNTIFS('Backlog détaillé'!A:A,B6,'Backlog détaillé'!G:G,"En cours") -> 0 | F6: =COUNTIFS('Backlog détaillé'!A:A,B6,'Backlog détaillé'!G:G,"Bloqué") -> 0 | G6: =IFERROR(D6/C6,0) -> 0
B7: Sprint 2 | C7: =COUNTIF('Backlog détaillé'!A:A,B7) -> 4 | D7: =COUNTIFS('Backlog détaillé'!A:A,B7,'Backlog détaillé'!G:G,"Terminé") -> 0 | E7: =COUNTIFS('Backlog détaillé'!A:A,B7,'Backlog détaillé'!G:G,"En cours") -> 0 | F7: =COUNTIFS('Backlog détaillé'!A:A,B7,'Backlog détaillé'!G:G,"Bloqué") -> 0 | G7: =IFERROR(D7/C7,0) -> 0
B8: Sprint 3 | C8: =COUNTIF('Backlog détaillé'!A:A,B8) -> 4 | D8: =COUNTIFS('Backlog détaillé'!A:A,B8,'Backlog détaillé'!G:G,"Terminé") -> 0 | E8: =COUNTIFS('Backlog détaillé'!A:A,B8,'Backlog détaillé'!G:G,"En cours") -> 0 | F8: =COUNTIFS('Backlog détaillé'!A:A,B8,'Backlog détaillé'!G:G,"Bloqué") -> 0 | G8: =IFERROR(D8/C8,0) -> 0
B9: Sprint 4 | C9: =COUNTIF('Backlog détaillé'!A:A,B9) -> 6 | D9: =COUNTIFS('Backlog détaillé'!A:A,B9,'Backlog détaillé'!G:G,"Terminé") -> 0 | E9: =COUNTIFS('Backlog détaillé'!A:A,B9,'Backlog détaillé'!G:G,"En cours") -> 0 | F9: =COUNTIFS('Backlog détaillé'!A:A,B9,'Backlog détaillé'!G:G,"Bloqué") -> 0 | G9: =IFERROR(D9/C9,0) -> 0
B10: Sprint 5 | C10: =COUNTIF('Backlog détaillé'!A:A,B10) -> 6 | D10: =COUNTIFS('Backlog détaillé'!A:A,B10,'Backlog détaillé'!G:G,"Terminé") -> 0 | E10: =COUNTIFS('Backlog détaillé'!A:A,B10,'Backlog détaillé'!G:G,"En cours") -> 0 | F10: =COUNTIFS('Backlog détaillé'!A:A,B10,'Backlog détaillé'!G:G,"Bloqué") -> 0 | G10: =IFERROR(D10/C10,0) -> 0
B11: Sprint 6 | C11: =COUNTIF('Backlog détaillé'!A:A,B11) -> 5 | D11: =COUNTIFS('Backlog détaillé'!A:A,B11,'Backlog détaillé'!G:G,"Terminé") -> 0 | E11: =COUNTIFS('Backlog détaillé'!A:A,B11,'Backlog détaillé'!G:G,"En cours") -> 0 | F11: =COUNTIFS('Backlog détaillé'!A:A,B11,'Backlog détaillé'!G:G,"Bloqué") -> 0 | G11: =IFERROR(D11/C11,0) -> 0
B12: Sprint 7 | C12: =COUNTIF('Backlog détaillé'!A:A,B12) -> 4 | D12: =COUNTIFS('Backlog détaillé'!A:A,B12,'Backlog détaillé'!G:G,"Terminé") -> 0 | E12: =COUNTIFS('Backlog détaillé'!A:A,B12,'Backlog détaillé'!G:G,"En cours") -> 0 | F12: =COUNTIFS('Backlog détaillé'!A:A,B12,'Backlog détaillé'!G:G,"Bloqué") -> 0 | G12: =IFERROR(D12/C12,0) -> 0
B13: Sprint 8 | C13: =COUNTIF('Backlog détaillé'!A:A,B13) -> 5 | D13: =COUNTIFS('Backlog détaillé'!A:A,B13,'Backlog détaillé'!G:G,"Terminé") -> 0 | E13: =COUNTIFS('Backlog détaillé'!A:A,B13,'Backlog détaillé'!G:G,"En cours") -> 0 | F13: =COUNTIFS('Backlog détaillé'!A:A,B13,'Backlog détaillé'!G:G,"Bloqué") -> 0 | G13: =IFERROR(D13/C13,0) -> 0
B14: Sprint 9 | C14: =COUNTIF('Backlog détaillé'!A:A,B14) -> 4 | D14: =COUNTIFS('Backlog détaillé'!A:A,B14,'Backlog détaillé'!G:G,"Terminé") -> 0 | E14: =COUNTIFS('Backlog détaillé'!A:A,B14,'Backlog détaillé'!G:G,"En cours") -> 0 | F14: =COUNTIFS('Backlog détaillé'!A:A,B14,'Backlog détaillé'!G:G,"Bloqué") -> 0 | G14: =IFERROR(D14/C14,0) -> 0
B15: Sprint 10 | C15: =COUNTIF('Backlog détaillé'!A:A,B15) -> 3 | D15: =COUNTIFS('Backlog détaillé'!A:A,B15,'Backlog détaillé'!G:G,"Terminé") -> 0 | E15: =COUNTIFS('Backlog détaillé'!A:A,B15,'Backlog détaillé'!G:G,"En cours") -> 0 | F15: =COUNTIFS('Backlog détaillé'!A:A,B15,'Backlog détaillé'!G:G,"Bloqué") -> 0 | G15: =IFERROR(D15/C15,0) -> 0
B16: Sprint 11 | C16: =COUNTIF('Backlog détaillé'!A:A,B16) -> 3 | D16: =COUNTIFS('Backlog détaillé'!A:A,B16,'Backlog détaillé'!G:G,"Terminé") -> 0 | E16: =COUNTIFS('Backlog détaillé'!A:A,B16,'Backlog détaillé'!G:G,"En cours") -> 0 | F16: =COUNTIFS('Backlog détaillé'!A:A,B16,'Backlog détaillé'!G:G,"Bloqué") -> 0 | G16: =IFERROR(D16/C16,0) -> 0
B17: TOTAL PROJET | C17: =SUM(C5:C16) -> 54 | D17: =SUM(D5:D16) -> 0 | E17: =SUM(E5:E16) -> 0 | F17: =SUM(F5:F16) -> 0 | G17: =IFERROR(D17/C17,0) -> 0
